<?xml version="1.0" ?>
<!-- =================================================================================== -->
<!-- |    This document was autogenerated by xacro from lwa4dmp500.urdf.xacro          | -->
<!-- |    EDITING THIS FILE BY HAND IS NOT RECOMMENDED                                 | -->
<!-- =================================================================================== -->
<robot name="mp500lwa4d" xmlns:xacro="http://www.ros.org/wiki/xacro">
  <!-- ros_control plugin -->
  <!--gazebo>
    <plugin name="gazebo_ros_control" filename="libgazebo_ros_control.so">
      <robotNamespace>/simple_robot</robotNamespace-->
  <!--<jointName>arm_1_joint, arm_2_joint, arm_3_joint, arm_4_joint, arm_5_joint, arm_6_joint, arm_7_joint, arm_8_joint, wheel_right_joint, wheel_left_joint</jointName>
      <robotParam>/robot_description</robotParam>-->
  <!--robotSimType>gazebo_ros_control/DefaultRobotHWSim</robotSimType>
    </plugin>
  </gazebo-->
  <!-- Left Wheel -->
  <gazebo reference="wheel_left_link">
    <turnGravityOff>false</turnGravityOff>
    <mu1>1.0</mu1>
    <mu2>1.0</mu2>
    <kp>10000000.0</kp>
    <kd>1.0</kd>
    <fdir1 value="1 0 0"/>
  </gazebo>
  <!-- Base Link -->
  <gazebo reference="base_link">
    <turnGravityOff>false</turnGravityOff>
    <mu1>0.0</mu1>
    <mu2>0.0</mu2>
    <surface>
      <friction>
        <ode>
          <mu>0</mu>
          <mu2>0</mu2>
          <!--slip1>1.0</slip1>
          <slip2>1.0</slip2-->
        </ode>
      </friction>
    </surface>
  </gazebo>
  <gazebo reference="castor_front">
    <turnGravityOff>false</turnGravityOff>
    <mu1>0.0</mu1>
    <mu2>0.0</mu2>
  </gazebo>
  <!-- Right Wheel -->
  <gazebo reference="wheel_right_link">
    <turnGravityOff>false</turnGravityOff>
    <mu1>1.0</mu1>
    <mu2>1.0</mu2>
    <kp>10000000.0</kp>
    <kd>1.0</kd>
    <fdir1 value="1 0 0"/>
  </gazebo>
  <gazebo reference="arm_base_link">
    <gravity>true</gravity>
    <self_collide>false</self_collide>
    <material value="Schunk/Black"/>
  </gazebo>
  <!--gazebo reference="arm_1_link">
      <gravity>true</gravity>
      <self_collide>false</self_collide>
      <material value="Schunk/LightGrey"/>
    </gazebo>

    <gazebo reference="arm_2_link">
      <gravity>true</gravity>
      <self_collide>false</self_collide>
      <material value="Schunk/Black"/>
    </gazebo>

    <gazebo reference="arm_3_link">
      <gravity>true</gravity>
      <self_collide>false</self_collide>
      <material value="Schunk/LightGrey"/>
    </gazebo>

    <gazebo reference="arm_4_link">
      <gravity>true</gravity>
      <self_collide>false</self_collide>
      <material value="Schunk/Black"/>
    </gazebo>

    <gazebo reference="arm_5_link">
      <gravity>true</gravity>
      <self_collide>false</self_collide>
      <material value="Schunk/LightGrey"/>
    </gazebo>

    <gazebo reference="arm_6_link">
      <gravity>true</gravity>
      <self_collide>false</self_collide>
      <material value="Schunk/Black"/>
    </gazebo>

    <gazebo reference="arm_7_link">
      <gravity>true</gravity>
      <self_collide>false</self_collide>
      <material value="Schunk/LightGrey"/>
    </gazebo-->
  <!--  <gazebo>
    <plugin name="ground_truth" filename="libgazebo_ros_p3d.so">
      <frameName>map</frameName>
      <bodyName>base_link</bodyName>
      <topicName>simple_robot/odom</topicName>
      <updateRate>30.0</updateRate>
    </plugin>
  </gazebo>-->
  <!--gazebo>
    <plugin name="differential_drive_controller" filename="libgazebo_ros_diff_drive.so">

      <robotNamespace>/mp500lwa4d</robotNamespace>
    		  
      <alwaysOn>true</alwaysOn>
      <updateRate>100</updateRate>
      <leftJoint>wheel_left_joint</leftJoint>
      <rightJoint>wheel_right_joint</rightJoint>
      <wheelSeparation>0.51</wheelSeparation>
      <wheelDiameter>0.125</wheelDiameter>
      <torque>45</torque>
      <commandTopic>/mp500lwa4d/mobile_base_controller/cmd_vel</commandTopic>
      <odometryTopic>odom</odometryTopic>
      <odometryFrame>map</odometryFrame>
      <robotBaseFrame>base_link</robotBaseFrame>
      
      <legacyMode>false</legacyMode>
      
      <rosDebugLevel>Debug</rosDebugLevel>
      <publishWheelTF>true</publishWheelTF>
      <publishWheelJointState>true</publishWheelJointState>
      <wheelAcceleration>0.01</wheelAcceleration>
      <wheelTorque>50</wheelTorque>
      <publishTf>1</publishTf>
      <odometrySource>encoder</odometrySource>
    </plugin-->
  <!--plugin name="joint_state_publisher" filename="libgazebo_ros_joint_state_publisher.so">
    <jointName>wheel_left_joint, wheel_right_joint</jointName>
    </plugin>>-->
  <!--/gazebo-->
  <material name="Schunk/LightGrey">
    <color rgba="0.7 0.7 0.7 1.0"/>
  </material>
  <material name="Schunk/DarkGrey">
    <color rgba="0.4 0.4 0.4 1.0"/>
  </material>
  <material name="Schunk/Black">
    <color rgba="0.0 0.0 0.0 1.0"/>
  </material>
  <material name="Schunk/DarkGolden">
    <color rgba="0.4 0.4 0.3 1.0"/>
  </material>
  <material name="Schunk/Blue">
    <color rgba="0.0 0.0 0.8 1.0"/>
  </material>
  <material name="Neobotix/Black">
    <color rgba="0.0 0.0 0.0 1.0"/>
  </material>
  <material name="Neobotix/Blue">
    <color rgba="0.0 0.0 0.8 1.0"/>
  </material>
  <material name="Neobotix/Green">
    <color rgba="0.0 0.8 0.0 1.0"/>
  </material>
  <material name="Neobotix/Grey">
    <color rgba="0.7 0.7 0.7 1.0"/>
  </material>
  <material name="Neobotix/Grey2">
    <color rgba="0.9 0.9 0.9 1.0"/>
  </material>
  <material name="Neobotix/Red">
    <color rgba="0.8 0.0 0.0 1.0"/>
  </material>
  <material name="Neobotix/White">
    <color rgba="1.0 1.0 1.0 1.0"/>
  </material>
  <material name="Neobotix/Yellow">
    <color rgba="1.0 1.0 0 10"/>
  </material>
  <gazebo reference="base_link">
    <gravity>true</gravity>
    <self_collide>false</self_collide>
    <material value="Gazebo/Blue"/>
  </gazebo>
  <gazebo reference="wheel_right_link">
    <gravity>true</gravity>
    <self_collide>false</self_collide>
    <material value="Gazebo/Black"/>
  </gazebo>
  <gazebo reference="wheel_left_link">
    <gravity>true</gravity>
    <self_collide>false</self_collide>
    <material value="Gazebo/Black"/>
  </gazebo>
  <gazebo reference="arm_base_link">
    <gravity>true</gravity>
    <self_collide>false</self_collide>
    <material value="Gazebo/Grey"/>
  </gazebo>
  <gazebo reference="arm_1_link">
    <gravity>true</gravity>
    <self_collide>false</self_collide>
    <material value="Gazebo/Black"/>
  </gazebo>
  <gazebo reference="arm_2_link">
    <gravity>true</gravity>
    <self_collide>false</self_collide>
    <material value="Gazebo/Blue"/>
  </gazebo>
  <gazebo reference="arm_3_link">
    <gravity>true</gravity>
    <self_collide>false</self_collide>
    <material value="Gazebo/Black"/>
  </gazebo>
  <gazebo reference="arm_4_link">
    <gravity>true</gravity>
    <self_collide>false</self_collide>
    <material value="Gazebo/Blue"/>
  </gazebo>
  <gazebo reference="arm_5_link">
    <gravity>true</gravity>
    <self_collide>false</self_collide>
    <material value="Gazebo/Black"/>
  </gazebo>
  <gazebo reference="arm_6_link">
    <gravity>true</gravity>
    <self_collide>false</self_collide>
    <material value="Gazebo/Blue"/>
  </gazebo>
  <gazebo reference="arm_7_link">
    <gravity>true</gravity>
    <self_collide>false</self_collide>
    <material value="Gazebo/Black"/>
  </gazebo>
  <!--gazebo reference="arm_ee_link">
    <gravity>true</gravity>
    <self_collide>false</self_collide>
    <material value="Gazebo/Blue"/>
  </gazebo-->
  <transmission name="wheel_right_trans">
    <type>transmission_interface/SimpleTransmission</type>
    <joint name="wheel_right_joint">
      <!--<hardwareInterface>hardware_interface/EffortJointInterface</hardwareInterface>-->
      <hardwareInterface>hardware_interface/VelocityJointInterface</hardwareInterface>
    </joint>
    <actuator name="wheel_right_motor">
      <hardwareInterface>hardware_interface/EffortJointInterface</hardwareInterface>
      <mechanicalReduction>0.1</mechanicalReduction>
    </actuator>
  </transmission>
  <transmission name="wheel_left_trans">
    <type>transmission_interface/SimpleTransmission</type>
    <joint name="wheel_left_joint">
      <!--<hardwareInterface>hardware_interface/EffortJointInterface</hardwareInterface>-->
      <hardwareInterface>hardware_interface/VelocityJointInterface</hardwareInterface>
    </joint>
    <actuator name="wheel_left_motor">
      <hardwareInterface>hardware_interface/EffortJointInterface</hardwareInterface>
      <mechanicalReduction>0.1</mechanicalReduction>
    </actuator>
  </transmission>
  <transmission name="arm_1_trans">
    <type>transmission_interface/SimpleTransmission</type>
    <joint name="arm_1_joint">
      <hardwareInterface>hardware_interface/PositionJointInterface</hardwareInterface>
      <!--hardwareInterface>hardware_interface/VelocityJointInterface</hardwareInterface>
      <hardwareInterface>EffortJointInterface</hardwareInterface-->
    </joint>
    <actuator name="arm_1_motor">
      <mechanicalReduction>0.05</mechanicalReduction>
    </actuator>
  </transmission>
  <transmission name="arm_2_trans">
    <type>transmission_interface/SimpleTransmission</type>
    <joint name="arm_2_joint">
      <hardwareInterface>hardware_interface/PositionJointInterface</hardwareInterface>
      <!--hardwareInterface>hardware_interface/VelocityJointInterface</hardwareInterface>
      <hardwareInterface>EffortJointInterface</hardwareInterface-->
    </joint>
    <actuator name="arm_2_motor">
      <mechanicalReduction>0.05</mechanicalReduction>
    </actuator>
  </transmission>
  <transmission name="arm_3_trans">
    <type>transmission_interface/SimpleTransmission</type>
    <joint name="arm_3_joint">
      <hardwareInterface>hardware_interface/PositionJointInterface</hardwareInterface>
      <!--hardwareInterface>hardware_interface/VelocityJointInterface</hardwareInterface>
      <hardwareInterface>EffortJointInterface</hardwareInterface-->
    </joint>
    <actuator name="arm_3_motor">
      <mechanicalReduction>0.05</mechanicalReduction>
    </actuator>
  </transmission>
  <transmission name="arm_4_trans">
    <type>transmission_interface/SimpleTransmission</type>
    <joint name="arm_4_joint">
      <hardwareInterface>hardware_interface/PositionJointInterface</hardwareInterface>
      <!--hardwareInterface>hardware_interface/VelocityJointInterface</hardwareInterface>
      <hardwareInterface>EffortJointInterface</hardwareInterface-->
    </joint>
    <actuator name="arm_4_motor">
      <mechanicalReduction>0.05</mechanicalReduction>
    </actuator>
  </transmission>
  <transmission name="arm_5_trans">
    <type>transmission_interface/SimpleTransmission</type>
    <joint name="arm_5_joint">
      <hardwareInterface>hardware_interface/PositionJointInterface</hardwareInterface>
      <!--hardwareInterface>hardware_interface/VelocityJointInterface</hardwareInterface>
      <hardwareInterface>EffortJointInterface</hardwareInterface-->
    </joint>
    <actuator name="arm_5_motor">
      <mechanicalReduction>0.05</mechanicalReduction>
    </actuator>
  </transmission>
  <transmission name="arm_6_trans">
    <type>transmission_interface/SimpleTransmission</type>
    <joint name="arm_6_joint">
      <hardwareInterface>hardware_interface/PositionJointInterface</hardwareInterface>
      <!--hardwareInterface>hardware_interface/VelocityJointInterface</hardwareInterface>
      <hardwareInterface>EffortJointInterface</hardwareInterface-->
    </joint>
    <actuator name="arm_6_motor">
      <mechanicalReduction>0.05</mechanicalReduction>
    </actuator>
  </transmission>
  <transmission name="arm_7_trans">
    <type>transmission_interface/SimpleTransmission</type>
    <joint name="arm_7_joint">
      <hardwareInterface>hardware_interface/PositionJointInterface</hardwareInterface>
      <!--hardwareInterface>hardware_interface/VelocityJointInterface</hardwareInterface>
      <hardwareInterface>EffortJointInterface</hardwareInterface-->
    </joint>
    <actuator name="arm_7_motor">
      <mechanicalReduction>0.05</mechanicalReduction>
    </actuator>
  </transmission>
  <!--transmission name="arm_ee_trans">
    <type>transmission_interface/SimpleTransmission</type>
    <joint name="arm_ee_joint">
      <hardwareInterface>hardware_interface/PositionJointInterface</hardwareInterface>
       </joint>
    <actuator name="arm_ee_motor">
      <mechanicalReduction>1</mechanicalReduction>
    </actuator>
  </transmission-->
  <!--    <gazebo>
      <plugin name="ros_control" filename="libhwi_switch_gazebo_ros_control.so">
        <robotNamespace>simple_robot</robotNamespace>
        &lt;!&ndash;<filterJointsParam>joint_names</filterJointsParam>&ndash;&gt;
      </plugin>
    </gazebo>-->
  <!--++++++++++++++++++++++++++base_link++++++++++++++++++++++++++++++++-->
  <link name="base_link">
    <inertial>
      <mass value="25.67"/>
      <origin rpy="0 0 0" xyz="0.15 0 0.2"/>
      <inertia ixx="0.54" ixy="0.0" ixz="0.0" iyy="1.08" iyz="0.0" izz="1.23"/>
    </inertial>
    <visual name="body">
      <!--origin xyz="0.0 0.0 0.234" rpy="0 0 1.57" /-->
      <!-- for cylinder -->
      <origin rpy="0 0 -1.57" xyz="0 0.0 0.09"/>
      <!-- for STL -->
      <geometry>
        <mesh filename="package://mp500lwa4d_description/meshes/MP500-BODY.STL" scale="0.01 0.01 0.01"/>
        <!--cylinder length="0.381" radius="0.2545"/-->
        <!--box size="0.445 0.277 0.17"/-->
      </geometry>
      <material name="Neobotix/Grey"/>
    </visual>
    <collision name="body_collision">
      <origin rpy="0 0 -1.57" xyz="0.15 0 0.2"/>
      <geometry>
        <box size="0.400 0.400 0.300"/>
        <!--cylinder length="0.381" radius="0.2545"/-->
      </geometry>
    </collision>
    <visual>
      <origin rpy="0 0 0" xyz="0.45 0 0.01"/>
      <geometry>
        <sphere radius="0.005"/>
      </geometry>
      <material name="Neobotix/Grey"/>
    </visual>
    <collision>
      <origin rpy="0 0 0" xyz="0.45 0 0.01"/>
      <geometry>
        <sphere radius="0.005"/>
      </geometry>
    </collision>
  </link>
  <!--+++++++++++++++++++wheel_left_link++++++++++++++++++++++++-->
  <link name="wheel_left_link" type="wheel">
    <inertial>
      <mass value="1.0"/>
      <origin rpy="0 0 0" xyz="0 0 0"/>
      <inertia ixx="0.0045" ixy="0" ixz="0" iyy="0.0078" iyz="0" izz="0.0045"/>
    </inertial>
    <visual>
      <origin rpy="0 0 -1.57" xyz="0 0 0"/>
      <geometry>
        <mesh filename="package://mp500lwa4d_description/meshes/MP500-WHEEL.STL" scale="0.01 0.01 0.01"/>
      </geometry>
      <material name="Neobotix/Black"/>
    </visual>
    <collision>
      <origin rpy="0 1.57 -1.57" xyz="0 0 0"/>
      <geometry>
        <cylinder length="0.085" radius="0.125"/>
      </geometry>
    </collision>
  </link>
  <!--+++++++++++++++++++wheel_left_joint++++++++++++++++++++++++-->
  <joint name="wheel_left_joint" type="revolute">
    <origin rpy="0 0 0" xyz="0 0.255 0.13"/>
    <axis xyz="0 1 0"/>
    <limit effort="10000.0" lower="-1e+16" upper="1e+16" velocity="11.6"/>
    <joint_properties damping="0.0" friction="0.0"/>
    <parent link="base_link"/>
    <child link="wheel_left_link"/>
  </joint>
  <!--+++++++++++++++++++wheel_right_link++++++++++++++++++++++++-->
  <link name="wheel_right_link" type="wheel">
    <inertial>
      <mass value="1"/>
      <origin rpy="0 0 0" xyz="0 0 0"/>
      <!--inertia ixx="0.0051" ixy="0" ixz="0" iyy="0.0051" iyz="0" izz="0.009" /-->
      <inertia ixx="0.0045" ixy="0" ixz="0" iyy="0.0078" iyz="0" izz="0.0045"/>
    </inertial>
    <visual>
      <origin rpy="0 0 -1.57" xyz="0 0 0"/>
      <geometry>
        <mesh filename="package://mp500lwa4d_description/meshes/MP500-WHEEL.STL" scale="0.01 0.01 0.01"/>
      </geometry>
      <material name="Neobotix/Black"/>
    </visual>
    <collision>
      <origin rpy="0 1.57 -1.57" xyz="0 0 0"/>
      <geometry>
        <cylinder length="0.085" radius="0.125"/>
      </geometry>
    </collision>
  </link>
  <!--+++++++++++++++++++wheel_right_joint++++++++++++++++++++++++-->
  <joint name="wheel_right_joint" type="revolute">
    <origin rpy="0 0 0" xyz="0 -0.255 0.13"/>
    <axis xyz="0 1 0"/>
    <limit effort="10000.0" lower="-1e+16" upper="1e+16" velocity="11.6"/>
    <joint_properties damping="0.0" friction="0.0"/>
    <parent link="base_link"/>
    <child link="wheel_right_link"/>
  </joint>
  <!-- joint between base_link and lwa4p_extended_connector_link -->
  <joint name="arm_podest_joint" type="fixed">
    <origin rpy="0 0 0" xyz="0.345 0 0.37"/>
    <parent link="base_link"/>
    <child link="arm_podest_link"/>
  </joint>
  <link name="arm_podest_link">
    <inertial>
      <mass value="0.01"/>
      <origin xyz="0 0 0"/>
      <inertia ixx="0.001" ixy="0.0" ixz="0.0" iyy="0.001" iyz="0.0" izz="0.001"/>
    </inertial>
    <visual>
      <geometry>
        <mesh filename="package://mp500lwa4d_description/meshes/arm_podest_link.stl"/>
      </geometry>
      <material name="Schunk/LightGrey"/>
    </visual>
    <collision>
      <geometry>
        <mesh filename="package://mp500lwa4d_description/meshes/arm_podest_link.stl"/>
      </geometry>
    </collision>
  </link>
  <joint name="arm_base_joint" type="fixed">
    <origin rpy="0 0 0" xyz="0 0 0.140"/>
    <axis xyz="0 0 1"/>
    <parent link="arm_podest_link"/>
    <child link="arm_base_link"/>
  </joint>
  <link name="arm_base_link">
    <!--xacro:default_inertial/-->
    <inertial>
      <mass value="0.01"/>
      <origin xyz="0 0 0"/>
      <inertia ixx="0.001" ixy="0.0" ixz="0.0" iyy="0.001" iyz="0.0" izz="0.001"/>
    </inertial>
  </link>
  <!-- joint between arm_base_link and arm_1_link -->
  <joint name="arm_1_joint" type="revolute">
    <origin rpy="0 0 0" xyz="0 0 0"/>
    <axis xyz="0 0 1"/>
    <parent link="arm_base_link"/>
    <child link="arm_1_link"/>
    <limit effort="216" lower="-3.12159265359" upper="3.12159265359" velocity="0.43633"/>
  </joint>
  <!-- arm_1_link-->
  <link name="arm_1_link">
    <inertial>
      <mass value="0.01"/>
      <origin xyz="0 0 0"/>
      <inertia ixx="0.001" ixy="0.0" ixz="0.0" iyy="0.001" iyz="0.0" izz="0.001"/>
    </inertial>
    <visual>
      <geometry>
        <mesh filename="package://mp500lwa4d_description/meshes/arm_1_link.stl"/>
      </geometry>
      <material name="Schunk/LightGrey"/>
    </visual>
    <collision>
      <geometry>
        <mesh filename="package://mp500lwa4d_description/meshes/arm_1_link.stl"/>
      </geometry>
    </collision>
  </link>
  <!-- joint between arm_1_link and arm_2_link -->
  <joint name="arm_2_joint" type="revolute">
    <origin rpy="-1.57079632679 -1.57079632679 0" xyz="0 0 0.24"/>
    <axis xyz="0 0 1"/>
    <parent link="arm_1_link"/>
    <child link="arm_2_link"/>
    <limit effort="216" lower="-2.12" upper="2.12" velocity="0.43633"/>
  </joint>
  <!-- arm_2_link -->
  <link name="arm_2_link">
    <inertial>
      <mass value="0.01"/>
      <origin xyz="0 0 0"/>
      <inertia ixx="0.001" ixy="0.0" ixz="0.0" iyy="0.001" iyz="0.0" izz="0.001"/>
    </inertial>
    <visual>
      <geometry>
        <mesh filename="package://mp500lwa4d_description/meshes/arm_2_link.stl"/>
      </geometry>
      <material name="Schunk/Black"/>
    </visual>
    <collision>
      <geometry>
        <mesh filename="package://mp500lwa4d_description/meshes/arm_2_link_collision.stl"/>
      </geometry>
    </collision>
  </link>
  <!-- joint between arm_2_link and arm_3_link -->
  <joint name="arm_3_joint" type="revolute">
    <origin rpy="1.57079632679 0 1.57079632679" xyz="0 0 0"/>
    <axis xyz="0 0 1"/>
    <parent link="arm_2_link"/>
    <child link="arm_3_link"/>
    <limit effort="81.5" lower="-3.12159265359" upper="3.12159265359" velocity="0.4189"/>
  </joint>
  <!-- arm_3_link -->
  <link name="arm_3_link">
    <inertial>
      <mass value="0.01"/>
      <origin xyz="0 0 0"/>
      <inertia ixx="0.001" ixy="0.0" ixz="0.0" iyy="0.001" iyz="0.0" izz="0.001"/>
    </inertial>
    <visual>
      <geometry>
        <mesh filename="package://mp500lwa4d_description/meshes/arm_3_link.stl"/>
      </geometry>
      <material name="Schunk/LightGrey"/>
    </visual>
    <collision>
      <geometry>
        <mesh filename="package://mp500lwa4d_description/meshes/arm_3_link_collision.stl"/>
      </geometry>
    </collision>
  </link>
  <!-- joint between arm_3_link and arm_4_link -->
  <joint name="arm_4_joint" type="revolute">
    <origin rpy="-1.57079632679 -1.57079632679 0" xyz="0 0 0.328"/>
    <axis xyz="0 0 1"/>
    <parent link="arm_3_link"/>
    <child link="arm_4_link"/>
    <limit effort="81.5" lower="-2.16" upper="2.16" velocity="0.4189"/>
  </joint>
  <!--arm_4_link -->
  <link name="arm_4_link">
    <inertial>
      <mass value="0.01"/>
      <origin xyz="0 0 0"/>
      <inertia ixx="0.001" ixy="0.0" ixz="0.0" iyy="0.001" iyz="0.0" izz="0.001"/>
    </inertial>
    <visual>
      <geometry>
        <mesh filename="package://mp500lwa4d_description/meshes/arm_4_link.stl"/>
      </geometry>
      <material name="Schunk/Black"/>
    </visual>
    <collision>
      <geometry>
        <mesh filename="package://mp500lwa4d_description/meshes/arm_4_link_collision.stl"/>
      </geometry>
    </collision>
  </link>
  <!-- joint between arm_4_link and arm_5_link -->
  <joint name="arm_5_joint" type="revolute">
    <origin rpy="1.57079632679 0 1.57079632679" xyz="0 0 0"/>
    <axis xyz="0 0 1"/>
    <parent link="arm_4_link"/>
    <child link="arm_5_link"/>
    <limit effort="20.7" lower="-3.12159265359" upper="3.12159265359" velocity="0.43633"/>
  </joint>
  <!-- arm_5_link -->
  <link name="arm_5_link">
    <inertial>
      <mass value="0.01"/>
      <origin xyz="0 0 0"/>
      <inertia ixx="0.001" ixy="0.0" ixz="0.0" iyy="0.001" iyz="0.0" izz="0.001"/>
    </inertial>
    <visual>
      <geometry>
        <mesh filename="package://mp500lwa4d_description/meshes/arm_5_link.stl"/>
      </geometry>
      <material name="Schunk/LightGrey"/>
    </visual>
    <collision>
      <geometry>
        <mesh filename="package://mp500lwa4d_description/meshes/arm_5_link_collision.stl"/>
      </geometry>
    </collision>
  </link>
  <!-- joint between arm_5_link and arm_6_link -->
  <joint name="arm_6_joint" type="revolute">
    <origin rpy="-1.57079632679 -1.57079632679 0" xyz="0 0 0.323"/>
    <axis xyz="0 0 1"/>
    <parent link="arm_5_link"/>
    <child link="arm_6_link"/>
    <limit effort="15" lower="-2.07" upper="2.07" velocity="1.2566"/>
  </joint>
  <!-- arm_6_link -->
  <link name="arm_6_link">
    <inertial>
      <mass value="0.01"/>
      <origin xyz="0 0 0"/>
      <inertia ixx="0.001" ixy="0.0" ixz="0.0" iyy="0.001" iyz="0.0" izz="0.001"/>
    </inertial>
    <visual>
      <geometry>
        <mesh filename="package://mp500lwa4d_description/meshes/arm_6_link.stl"/>
      </geometry>
      <material name="Schunk/Black"/>
    </visual>
    <collision>
      <geometry>
        <mesh filename="package://mp500lwa4d_description/meshes/arm_6_link_collision.stl"/>
      </geometry>
    </collision>
  </link>
  <!-- joint between arm_6_link and arm_7_link -->
  <joint name="arm_7_joint" type="revolute">
    <origin rpy="1.57079632679 0 1.57079632679" xyz="0 0 0"/>
    <axis xyz="0 0 1"/>
    <parent link="arm_6_link"/>
    <child link="arm_7_link"/>
    <limit effort="15" lower="-2.94" upper="2.94" velocity="1.2566"/>
  </joint>
  <!--arm_7_link -->
  <link name="arm_7_link">
    <inertial>
      <mass value="0.01"/>
      <origin xyz="0 0 0"/>
      <inertia ixx="0.001" ixy="0.0" ixz="0.0" iyy="0.001" iyz="0.0" izz="0.001"/>
    </inertial>
    <visual>
      <geometry>
        <mesh filename="package://mp500lwa4d_description/meshes/arm_7_link.stl"/>
      </geometry>
      <material name="Schunk/LightGrey"/>
    </visual>
    <collision>
      <geometry>
        <mesh filename="package://mp500lwa4d_description/meshes/arm_7_link.stl"/>
      </geometry>
    </collision>
  </link>
  <joint name="arm_ee_joint" type="fixed">
    <origin rpy="0 0 0" xyz="0 0 0.0824"/>
    <axis xyz="0 0 1"/>
    <parent link="arm_7_link"/>
    <child link="arm_ee_link"/>
  </joint>
  <link name="arm_ee_link">
    <inertial>
      <mass value="0.01"/>
      <origin xyz="0 0 0"/>
      <inertia ixx="0.001" ixy="0.0" ixz="0.0" iyy="0.001" iyz="0.0" izz="0.001"/>
    </inertial>
  </link>
  <gazebo>
    <plugin filename="libgazebo_ros_diff_drive.so" name="differential_drive_controller">
      <robotNamespace>/mp500lwa4d</robotNamespace>
      <alwaysOn>true</alwaysOn>
      <updateRate>100</updateRate>
      <leftJoint>wheel_left_joint</leftJoint>
      <rightJoint>wheel_right_joint</rightJoint>
      <wheelSeparation>0.51</wheelSeparation>
      <wheelDiameter>0.125</wheelDiameter>
      <torque>45</torque>
      <commandTopic>/mp500lwa4d/mobile_base_controller/cmd_vel</commandTopic>
      <odometryTopic>odom</odometryTopic>
      <odometryFrame>map</odometryFrame>
      <robotBaseFrame>/mp500lwa4d/base_link</robotBaseFrame>
      <legacyMode>false</legacyMode>
      <rosDebugLevel>Debug</rosDebugLevel>
      <publishWheelTF>true</publishWheelTF>
      <publishWheelJointState>true</publishWheelJointState>
      <wheelAcceleration>0.01</wheelAcceleration>
      <wheelTorque>45</wheelTorque>
      <publishTf>1</publishTf>
      <odometrySource>encoder</odometrySource>
    </plugin>
    <!--plugin name="ros_control" filename="libhwi_switch_gazebo_ros_control.so"-->
    <plugin filename="libgazebo_ros_control.so" name="gazebo_ros_control">
      <!--plugin name="ros_control" filename="libhwi_switch_gazebo_ros_control.so"-->
      <robotNamespace>mp500lwa4d</robotNamespace>
      <filterJointsParam>joint_names</filterJointsParam>
    </plugin>
    <!--plugin name="joint_state_publisher" filename="libgazebo_ros_joint_state_publisher.so">
  <jointName>wheel_left_joint, wheel_right_joint</jointName>
  </plugin>>-->
  </gazebo>
</robot>

